
<robot  name="SARA" version="1.0" >

<link name="dummy"> </link>


     <joint name="shoulder_roll_joint" type="revolute">
       <parent link="dummy"/>
       <child link="clavicular_link"/>
       <dynamics damping="0.1"/>
       <limit effort="10000.0" lower="-1.57" upper="1.5" velocity="0.57"/>
       <origin xyz="0 -0.1437625 0.01166" rpy="0 -1.57 0"/>
       <axis xyz="0 0 1" />
     </joint>

     <link name="clavicular_link">
       <inertial>
         <mass value="0.28506911" />
         <origin xyz="0.0 -0.03225261 -0.01842117" rpy="0 0 0" />
         <inertia ixx = "0.00040678" ixy="0.0" ixz = "-0.00000004"
                  iyy = "0.00039958" iyz = "-0.00003453"
                  izz = "0.00059825" />
       </inertial>
     </link>

     <joint name="shoulder_pitch_joint" type="revolute">
       <parent link="clavicular_link"/>
       <child link="upper_arm_upper_link"/>
       <dynamics damping="0.1"/>
       <limit effort="10000.0" lower="-1.9" upper="0.6" velocity="1"/>
       <origin xyz="0 -0.085 0" rpy="-1.57 0 0" />
       <axis xyz="0 0 1" />
     </joint>

     <link name="upper_arm_upper_link">
         <inertial>
           <mass value="0.28506911" />
           <origin xyz="-0.03225261 0 -0.01842117" rpy="0 0 0"/>
           <inertia ixx = "0.00039958" ixy="0" ixz = "-0.00003453" iyy = "0.00040678" iyz = "0.00000004" izz = "0.00059825" />
         </inertial>
     </link>

     <joint name="$shoulder_yaw_joint" type="revolute">
       <parent link="upper_arm_upper_link"/>
       <child link="upper_arm_lower_link"/>
       <dynamics damping="0.1"/>
       <limit effort="10000.0" lower="-1.5" upper="1.3" velocity="1"/>
       <origin xyz="-0.085 0 0" rpy="1.5708 0 1.5708" />
       <axis xyz="0 0 1" />
     </joint>

     <link name="upper_arm_lower_link">
       <inertial>
         <mass value="0.85240803" />
         <origin xyz="-0.00168302 0.00155140 -0.13913505" rpy="0 0 0"/>
         <inertia ixx = "0.00538199" ixy = "-0.00000635" ixz = "0.00012863"
                  iyy = "0.00562525" iyz = "-0.00012986"
                  izz = "0.00050159" />
       </inertial>
     </link>

      <joint name="elbow_pitch_joint" type="revolute">
        <parent link="upper_arm_lower_link"/>
        <child link="forearm_upper_link"/>
        <dynamics damping="0.1"/>
        <limit effort="10000.0" lower="-0.75" upper="1.40" velocity="1"/>
        <origin xyz="0 0 -0.31" rpy="-1.5708 -1.5708 0" />
        <axis xyz="0 0 1" />
      </joint>

      <link name="forearm_upper_link">
        <inertial>
          <mass value="0.28300045" />
          <origin xyz="0.00000207 0.03922132 -0.01628605" rpy="0 0 0"/>
          <inertia ixx = "0.00036109" ixy = "0.0" ixz = "-0.00000002"
                   iyy = "0.00029872" iyz = "0.00001701"
                   izz = "0.00055069" />
        </inertial>
      </link>

     <joint name="elbow_yaw_joint" type="revolute">
       <parent link="forearm_upper_link"/>
       <child link="forearm_lower_link"/>
       <dynamics damping="0.1"/>
       <limit effort="10000.0" lower="-3" upper="3" velocity="1"/>
       <origin xyz="0 0.0945 0" rpy="1.5708 -3.14159 0" />
       <axis xyz="0 0 1" />
     </joint>

     <link name="forearm_lower_link">
       <inertial>
         <mass value="0.1177" />
         <origin xyz="0.0 -0.00000184 -0.03625492" rpy="0 0 0" />
         <inertia ixx = "0.54274952" ixy = "0.0" ixz = "0.0"
                  iyy = "1.03078569" iyz = "0.0"
                  izz = "0.00010905" />
       </inertial>
     </link>

     <joint name="wrist_joint" type="fixed">
       <parent link="forearm_lower_link"/>
       <child link="wrist_upper_link"/>
       <limit effort="10000.0" lower="-3.1416" upper="3.1416" velocity="1"/>
       <origin xyz="0 0 -0.05124" rpy="1.5708 -1.5708 0" />
       <axis xyz="0 1 0" />
     </joint>

     <link name="wrist_upper_link">
       <inertial>
         <mass value="0.1956991" />
         <origin xyz="-0.03893593 0.00017228 -0.00000284" rpy="0 0 0"/>
         <inertia ixx = "0.00007035" ixy = "-0.00000150" ixz = "0.0"
                  iyy = "0.00011510" iyz = "0.0"
                  izz = "0.00013235" />
       </inertial>
     </link>

     <joint name="wrist_pitch_joint" type="revolute">
       <parent link="wrist_upper_link"/>
       <child link="wrist_lower_link"/>
       <dynamics damping="0.1"/>
       <limit effort="10000.0" lower="-1.5" upper="1.5" velocity="1"/>
       <origin xyz="-0.0606 0 0" rpy="1.5708 -1.5708 0" />
       <axis xyz="0 0 1" />
     </joint>

     <link name="wrist_lower_link">
       <inertial>
         <mass value="0.18747684" />
         <origin xyz="0.00001243 0.05721169 0.0" rpy=" 0 0 0"/>
         <inertia ixx = "0.00015391" ixy = "-0.00000060" ixz = "0.0"
                  iyy = "0.00006260" iyz = "0.0"
                  izz = "0.00015218" />
       </inertial>
     </link>

     <joint name="wrist_roll_joint" type="revolute">
       <parent link="wrist_lower_link"/>
       <child link="socket_link"/>
       <dynamics damping="0.1"/>
       <limit effort="10000.0" lower="-1.5" upper="1.5" velocity="1"/>
       <origin xyz="0 0.084375 0" rpy="1.5708 0 0" />
       <axis xyz="1 0 0" />
     </joint>

     <link name="socket_link">
       <inertial>
         <mass value="0.02796" />
         <origin xyz="0.0 0.0 -0.01570460" rpy="0 0 0"/>
         <inertia ixx = "0.00000889" ixy = "0.0" ixz = "0.0"
                  iyy= "0.00002569" iyz = "0.0"
                  izz = "0.00002493" />
       </inertial>
     </link>

     <joint name="effector" type="fixed">
       <parent link="socket_link"/>
       <child link="dummy2"/>
       <dynamics damping="0.1"/>
       <limit effort="10000.0" lower="-1.49" upper="1.49" velocity="1"/>
       <origin xyz="0 0 -0.2" rpy="1.57 1.57 0" />
        <axis xyz="0 1 0" />
     </joint>

<link name="dummy2"> </link>



</robot>
